Workbook

Sheet Bibliotheque
A1: N°Obs | B1: Quels est votre genre ? | C1: Dans quelle tranche d'âge vous situez-vous ? | D1: Quelle est votre situation professionnelle actuelle ? | E1: Autre : | F1: Dans quel type de logement vivez-vous actuellement ? | G1: Autre : : | H1: Quel est le code postal de votre lieu de résidence ? | I1: Département | J1: Comment définiriez-vous l'emplacement de votre domicile par rapport au centre-ville ? | K1: Une bibliothèque d'objets à Besançon vous intéresserait-elle ? | L1: Quelles raisons vous motiveraient à utiliser une bibliothèque d'objets ? (Plusieurs réponses possibles) | M1: Autre : :2 | N1: Accepteriez-vous de partager certains de vos objets personnels avec d'autres utilisateurs ? | O1: Si oui, quels types d'objets seriez-vous prêt(e) à partager ? | P1: Avez-vous déjà utilisé des services de location ou de prêt d'objets ?_ | Q1: Accepteriez-vous de payer une cotisation pour accéder à une bibliothèque d'objets ? | R1: Pour un objet d'une valeur de 200€ neuf, quel prix maximum de location journalière seriez-vous prêt(e) à payer ? | S1: Autre : :3 | T1: Quels critères considérez-vous comme essentiels pour utiliser un service de prêt d'objets ? (Plusieurs réponses possibles) | U1: Autre : :4 | V1: Souhaitez-vous recevoir des informations sur l'évolution de ce projet ? | W1: Nom + prénom : | X1: E-mail : | Y1: Téléphone (facultatif) : | Z1: Clé | AA1: Date de saisie | AB1: Date de dernière modification | AC1: Date de dernier enregistrement | AD1: Temps de saisie | AE1: Langue | AF1: Progression | AG1: Dernière question saisie | AH1: Origine | AI1: Appareil utilisé pour la saisie | AJ1: Campagne de diffusion
A2: 1 | Z2: 5324-DVG6 | AA2: 28/03/2025 14:49:02 | AC2: 28/03/2025 14:51:32 | AD2: 150.11849 | AE2: FR | AF2: Terminé | AH2: direct | AI2: Smartphone | AJ2: aa588d67cccf4d2bb8f808dd4fdad167
A3: 2 | B3: Non-binaire | C3: 35-44 ans | D3: En activité professionnelle | F3: Appartement | H3: 25720 | I3: 25 | J3: Proche du centre | K3: Oui | L3: Préoccupations environnementales;Réduire l'accumulation d'objets | N3: Oui , avec certaines conditions | O3: Cuisine | P3: Non, jamais | Q3: Non, je ne souhaiterai pas payer de cotisation | R3: 10€ | T3: Disponibilité des objets;Facilité de réservation et d'emprunt;Prix abordable | V3: Je souhaite être informé(e) des prochaines étapes | W3: Thibault Aubertin | X3: aubertin.thibault@gmail.com | Z3: 8CLM-Y3Q4 | AA3: 07/04/2025 22:27:04 | AC3: 07/04/2025 22:31:38 | AD3: 274.23552 | AE3: FR | AF3: Terminé | AH3: direct | AI3: PC | AJ3: aa588d67cccf4d2bb8f808dd4fdad167
A4: 3 | B4: Femme | C4: 35-44 ans | D4: En activité professionnelle | F4: Maison | H4: 25000 | I4: 25 | J4: Centre | K4: Oui | L4: Manque d'espace de stockage;Contraintes budgétaires;Préoccupations environnementales;Réduire l'accumulation d'objets | N4: Oui , avec certaines conditions | O4: Camping / Randonnée | P4: Non, jamais | Q4: Non, je ne souhaiterai pas payer de cotisation | R4: 10€ | T4: Disponibilité des objets;Facilité de réservation et d'emprunt;Prix abordable | V4: Je souhaite être informé(e) des prochaines étapes | W4: molherat caroline | X4: molheratcaroline@yahoo.fr | Z4: YVWD-3ASA | AA4: 15/04/2025 18:57:08 | AC4: 15/04/2025 19:01:18 | AD4: 249.76467 | AE4: FR | AF4: Terminé | AH4: direct | AI4: PC | AJ4: aa588d67cccf4d2bb8f808dd4fdad167
A5: 4 | B5: Femme | C5: 45-54 ans | D5: En activité professionnelle | F5: Appartement | H5: 25000 | I5: 25 | J5: Proche du centre | K5: Oui | L5: Manque d'espace de stockage;Contraintes budgétaires;Préoccupations environnementales;Envie de partager des compétences;Réduire l'accumulation d'objets;Éviter les frais d'entretien | N5: Non , je souhaite uniquement emprunter | P5: Oui, occasionnellement | Q5: Non, je ne souhaiterai pas payer de cotisation | R5: 10€ | T5: Facilité de réservation et d'emprunt;Prix abordable;Durée de prêt flexible;Support et explications d'utilisation | V5: Je souhaite être informé(e) des prochaines étapes | W5: Humbett Alice | X5: Alice.humbert1@orange.fr | Y5: 06 84 77 64 63 | Z5: EW34-K8LY | AA5: 15/04/2025 19:41:24 | AC5: 15/04/2025 19:44:43 | AD5: 199.33645 | AE5: FR | AF5: Terminé | AH5: direct | AI5: Smartphone | AJ5: aa588d67cccf4d2bb8f808dd4fdad167
A6: 5 | B6: Femme | C6: 25-34 ans | D6: En activité professionnelle | F6: Maison | H6: 25870 | I6: 25 | J6: Zone rurale | K6: Oui | L6: Contraintes budgétaires;Préoccupations environnementales;Réduire l'accumulation d'objets | N6: Oui , avec certaines conditions | O6: Jeux extérieurs | P6: Non, jamais | Q6: Non, je ne souhaiterai pas payer de cotisation | R6: 10€ | T6: Disponibilité des objets;Facilité de réservation et d'emprunt;Prix abordable;Durée de prêt flexible;Support et explications d'utilisation | V6: Je souhaite être informé(e) des prochaines étapes | W6: Charmoille Désirée | X6: charmoilledesiree@yahoo.fr | Z6: W4K5-6DN9 | AA6: 15/04/2025 21:12:24 | AC6: 15/04/2025 21:17:56 | AD6: 331.11882 | AE6: FR | AF6: Terminé | AH6: direct | AI6: Smartphone | AJ6: aa588d67cccf4d2bb8f808dd4fdad167
A7: 6 | B7: Femme | C7: 35-44 ans | D7: En activité professionnelle | F7: Maison | H7: 25000 | I7: 25 | J7: Proche du centre | K7: Oui | L7: Manque d'espace de stockage;Contraintes budgétaires;Préoccupations environnementales;Envie de partager des compétences;Réduire l'accumulation d'objets | N7: Oui , avec certaines conditions | P7: Non, jamais | R7: 10€ | T7: Facilité de réservation et d'emprunt;Prix abordable;Durée de prêt flexible | V7: Je souhaite être informé(e) des prochaines étapes | W7: Chazal Anne-Cécile | X7: chazalannececile@gmail.com | Z7: SR6L-FV73 | AA7: 15/04/2025 21:43:59 | AC7: 15/04/2025 21:47:18 | AD7: 198.9303 | AE7: FR | AF7: Terminé | AH7: direct | AI7: Smartphone | AJ7: aa588d67cccf4d2bb8f808dd4fdad167
A8: 7 | B8: Femme | C8: 35-44 ans | D8: En activité professionnelle | F8: Appartement | H8: 25000 | I8: 25 | J8: Proche du centre | K8: Oui | L8: Contraintes budgétaires;Préoccupations environnementales;Réduire l'accumulation d'objets | N8: Oui , avec certaines conditions | P8: Non, jamais | Q8: Non, je ne souhaiterai pas payer de cotisation | R8: 10€ | T8: Disponibilité des objets;Facilité de réservation et d'emprunt;Prix abordable | V8: Je souhaite être informé(e) des prochaines étapes | W8: THIEBAUD AURELIE | X8: aurelie.thiebaud@yahoo.fr | Y8: 0667427026 | Z8: W7Q7-ZGU7 | AA8: 18/04/2025 09:33:09 | AC8: 18/04/2025 09:36:14 | AD8: 184.8363 | AE8: FR | AF8: Terminé | AH8: direct | AI8: PC | AJ8: aa588d67cccf4d2bb8f808dd4fdad167
A9: 8 | B9: Homme | C9: 35-44 ans | D9: En activité professionnelle | F9: Maison | H9: 25660 | I9: 25 | J9: Périphérie | K9: Oui | L9: Contraintes budgétaires;Préoccupations environnementales;Envie de partager des compétences;Réduire l'accumulation d'objets | N9: Oui , avec certaines conditions | P9: Oui, occasionnellement | Q9: Non, je ne souhaiterai pas payer de cotisation | R9: 10€ | T9: Facilité de réservation et d'emprunt;Prix abordable | V9: Je ne souhaite pas être tenu(e) informé | Z9: WJHW-GMDA | AA9: 18/04/2025 14:30:15 | AC9: 18/04/2025 14:32:37 | AD9: 142.01246 | AE9: FR | AF9: Terminé | AH9: direct | AI9: PC | AJ9: aa588d67cccf4d2bb8f808dd4fdad167
A10: 9 | B10: Femme | C10: 35-44 ans | D10: En activité professionnelle | F10: Appartement | H10: 25000 | I10: 25 | J10: Hyper-centre | K10: Oui | L10: Manque d'espace de stockage;Préoccupations environnementales;Réduire l'accumulation d'objets | N10: Oui , avec certaines conditions | O10: Multimédia | P10: Oui, occasionnellement | Q10: Non, je ne souhaiterai pas payer de cotisation | R10: 10€ | T10: Disponibilité des objets;Prix abordable | V10: Je souhaite être informé(e) des prochaines étapes | W10: Vouillot Cécile | X10: cecile.vouillot@gmail.com | Z10: VCLA-ULC5 | AA10: 20/04/2025 19:39:09 | AC10: 20/04/2025 19:43:24 | AD10: 255.65148 | AE10: FR | AF10: Terminé | AH10: direct | AI10: PC | AJ10: aa588d67cccf4d2bb8f808dd4fdad167
A11: 10 | B11: Homme | C11: 35-44 ans | D11: En activité professionnelle | F11: Appartement | H11: 25000 | I11: 25 | J11: Hyper-centre | K11: Peut-être | L11: Manque d'espace de stockage;Préoccupations environnementales;Envie de partager des compétences | N11: Non , je souhaite uniquement emprunter | P11: Oui, régulièrement | Q11: Non, je ne souhaiterai pas payer de cotisation | R11: 15€ | T11: Disponibilité des objets;Facilité de réservation et d'emprunt;Autre : | U11: Qualité des outils et maintenance garantie, bon état de fonctionnement assuré (outils électriques / électroportatifs en particulier). | V11: Je souhaite être informé(e) des prochaines étapes | W11: Brand Xavier | X11: xavier.brand@free.fr | Z11: UBAU-ZDCP | AA11: 22/04/2025 10:53:03 | AC11: 22/04/2025 10:59:39 | AD11: 395.54302 | AE11: FR | AF11: Terminé | AH11: direct | AI11: PC | AJ11: aa588d67cccf4d2bb8f808dd4fdad167
A12: 11 | B12: Homme | C12: 45-54 ans | D12: Retraité(e) | F12: Appartement | H12: 25000 | I12: 25 | J12: Centre | K12: Oui | L12: Préoccupations environnementales;Envie de partager des compétences;Réduire l'accumulation d'objets | N12: Oui , avec certaines conditions | O12: Ménage | P12: Oui, occasionnellement | Q12: Non, je ne souhaiterai pas payer de cotisation | R12: 10€ | T12: Disponibilité des objets;Facilité de réservation et d'emprunt;Prix abordable;Durée de prêt flexible | V12: Je souhaite être informé(e) des prochaines étapes | W12: pierre corneloup | X12: piou25@laposte.net | Z12: V4VM-2XT2 | AA12: 03/05/2025 18:01:28 | AC12: 03/05/2025 18:05:58 | AD12: 270.1967 | AE12: FR | AF12: Terminé | AH12: direct | AI12: PC | AJ12: aa588d67cccf4d2bb8f808dd4fdad167
A13: 12 | B13: Homme | C13: 45-54 ans | D13: En activité professionnelle | F13: Maison | H13: 25000 | I13: 25 | J13: Proche du centre | K13: Oui | L13: Préoccupations environnementales;Réduire l'accumulation d'objets;Éviter les frais d'entretien | N13: Oui , avec certaines conditions | P13: Oui, occasionnellement | R13: 10€ | T13: Facilité de réservation et d'emprunt;Prix abordable | V13: Je souhaite être informé(e) des prochaines étapes | W13: Vincent Lecomte | X13: vincent25@zaclys.net | Z13: DGR9-RJRU | AA13: 03/05/2025 19:48:57 | AC13: 03/05/2025 19:53:41 | AD13: 283.48339 | AE13: FR | AF13: Terminé | AH13: direct | AI13: PC | AJ13: aa588d67cccf4d2bb8f808dd4fdad167
A14: 13 | B14: Femme | C14: 35-44 ans | D14: En activité professionnelle | F14: Appartement | H14: 25000 | I14: 25 | J14: Centre | K14: Oui | L14: Manque d'espace de stockage;Contraintes budgétaires;Préoccupations environnementales;Envie de partager des compétences;Réduire l'accumulation d'objets;Éviter les frais d'entretien | N14: Oui , avec certaines conditions | O14: Animalerie | P14: Oui, occasionnellement | Q14: Non, je ne souhaiterai pas payer de cotisation | R14: 10€ | T14: Disponibilité des objets;Facilité de réservation et d'emprunt;Prix abordable;Support et explications d'utilisation | V14: Je souhaite être informé(e) des prochaines étapes | W14: Geslin Marianne | X14: mariannegeslin@yahoo.com | Z14: EHVJ-D3C7 | AA14: 03/05/2025 21:23:26 | AC14: 03/05/2025 21:26:29 | AD14: 183.66787 | AE14: FR | AF14: Terminé | AH14: direct | AI14: Smartphone | AJ14: aa588d67cccf4d2bb8f808dd4fdad167
A15: 14 | B15: Femme | C15: 35-44 ans | D15: En activité professionnelle | F15: Maison | H15: 25000 | I15: 25 | J15: Centre | K15: Peut-être | L15: Préoccupations environnementales;Réduire l'accumulation d'objets;Éviter les frais d'entretien | N15: Non , je souhaite uniquement emprunter | P15: Oui, occasionnellement | R15: 15€ | T15: Disponibilité des objets;Facilité de réservation et d'emprunt;Prix abordable;Durée de prêt flexible;Support et explications d'utilisation | V15: Je ne souhaite pas être tenu(e) informé | Z15: Y9JB-F93P | AA15: 04/05/2025 13:39:02 | AC15: 04/05/2025 13:41:47 | AD15: 164.61082 | AE15: FR | AF15: Terminé | AH15: direct | AI15: Smartphone | AJ15: aa588d67cccf4d2bb8f808dd4fdad167
A16: 15 | B16: Femme | C16: 35-44 ans | D16: En activité professionnelle | F16: Maison | H16: 25000 | I16: 25 | J16: Proche du centre | K16: Oui | L16: Préoccupations environnementales;Réduire l'accumulation d'objets | N16: Oui , avec certaines conditions | P16: Oui, occasionnellement | R16: 10€ | T16: Facilité de réservation et d'emprunt;Durée de prêt flexible | V16: Je ne souhaite pas être tenu(e) informé | Z16: 9VD9-NJMS | AA16: 04/05/2025 21:01:15 | AC16: 04/05/2025 21:11:41 | AD16: 625.30611 | AE16: FR | AF16: Terminé | AH16: direct | AI16: PC | AJ16: aa588d67cccf4d2bb8f808dd4fdad167
A17: 16 | B17: Femme | C17: 35-44 ans | D17: En activité professionnelle | F17: Appartement | H17: 25000 | I17: 25 | J17: Proche du centre | K17: Oui | L17: Manque d'espace de stockage;Préoccupations environnementales;Réduire l'accumulation d'objets | N17: Oui , sans condition particulière | O17: Jardinage | P17: Non, jamais | Q17: Non, je ne souhaiterai pas payer de cotisation | R17: 10€ | T17: Facilité de réservation et d'emprunt;Support et explications d'utilisation | V17: Je souhaite être informé(e) des prochaines étapes | W17: Ludivine Petit | X17: luludivinepetit@yahoo.fr | Y17: 0682413213 | Z17: GUGF-FGQZ | AA17: 04/05/2025 21:37:45 | AC17: 04/05/2025 21:44:28 | AD17: 403.71225 | AE17: FR | AF17: Terminé | AH17: direct | AI17: Smartphone | AJ17: aa588d67cccf4d2bb8f808dd4fdad167
A18: 17 | B18: Femme | C18: 35-44 ans | D18: En activité professionnelle | F18: Appartement | H18: 25000 | I18: 25 | J18: Proche du centre | K18: Oui | L18: Préoccupations environnementales;Réduire l'accumulation d'objets | N18: Oui , sans condition particulière | P18: Non, jamais | Q18: Non, je ne souhaiterai pas payer de cotisation | R18: 5€ | T18: Facilité de réservation et d'emprunt;Prix abordable | V18: Je souhaite être informé(e) des prochaines étapes | W18: Maillard-Salin Coline | X18: Maillardsalin.c@gmail.com | Y18: 0660570106 | Z18: YCH9-2CS6 | AA18: 04/05/2025 21:53:57 | AC18: 04/05/2025 22:01:04 | AD18: 426.10157 | AE18: FR | AF18: Terminé | AH18: direct | AI18: Smartphone | AJ18: aa588d67cccf4d2bb8f808dd4fdad167
A19: 18 | B19: Femme | C19: 18-24 ans | D19: Étudiant(e) | F19: Appartement | H19: 90300 | I19: 90 | J19: Proche du centre | K19: Oui | L19: Réduire l'accumulation d'objets | N19: Oui , sans condition particulière | O19: Puériculture | P19: Non, jamais | R19: 5€ | T19: Facilité de réservation et d'emprunt;Prix abordable;Durée de prêt flexible;Support et explications d'utilisation | V19: Je ne souhaite pas être tenu(e) informé | Z19: ZWQQ-L7XK | AA19: 05/05/2025 11:23:04 | AC19: 05/05/2025 11:24:54 | AD19: 110.63317 | AE19: FR | AF19: Terminé | AH19: direct | AI19: Smartphone | AJ19: aa588d67cccf4d2bb8f808dd4fdad167
A20: 19 | B20: Femme | C20: 18-24 ans | D20: Étudiant(e) | F20: Appartement | H20: 90000 | I20: 90 | J20: Centre | K20: Peut-être | L20: Contraintes budgétaires | N20: Non , je souhaite uniquement emprunter | P20: Oui, occasionnellement | R20: 5€ | T20: Facilité de réservation et d'emprunt | V20: Je ne souhaite pas être tenu(e) informé | Z20: 8AGF-E7AK | AA20: 05/05/2025 11:25:16 | AC20: 05/05/2025 11:26:55 | AD20: 99.117933 | AE20: FR | AF20: Terminé | AH20: direct | AI20: Tablette | AJ20: aa588d67cccf4d2bb8f808dd4fdad167
A21: 20 | B21: Femme | C21: 18-24 ans | D21: Étudiant(e) | F21: Appartement | H21: 90000 | I21: 90 | J21: Proche du centre | K21: Non | L21: Réduire l'accumulation d'objets | N21: Non , je souhaite uniquement emprunter | P21: Non, jamais | R21: 20 | T21: Facilité de réservation et d'emprunt;Prix abordable;Support et explications d'utilisation | V21: Je ne souhaite pas être tenu(e) informé | Z21: 2B6Q-7M2L | AA21: 05/05/2025 11:24:07 | AC21: 05/05/2025 11:26:59 | AD21: 172.25142 | AE21: FR | AF21: Terminé | AH21: direct | AI21: Smartphone | AJ21: aa588d67cccf4d2bb8f808dd4fdad167
A22: 21 | B22: Femme | C22: 18-24 ans | D22: Étudiant(e) | F22: Appartement | H22: 90000 | I22: 90 | J22: Zone rurale | K22: Non | L22: Contraintes budgétaires | N22: Non , je souhaite uniquement emprunter | P22: Oui, occasionnellement | R22: 20 | T22: Disponibilité des objets;Facilité de réservation et d'emprunt;Prix abordable | V22: Je ne souhaite pas être tenu(e) informé | Z22: K4SW-7NAP | AA22: 05/05/2025 11:25:21 | AC22: 05/05/2025 11:27:10 | AD22: 108.77068 | AE22: FR | AF22: Terminé | AH22: direct | AI22: Smartphone | AJ22: aa588d67cccf4d2bb8f808dd4fdad167
A23: 22 | B23: Homme | C23: 18-24 ans | D23: Étudiant(e) | F23: Appartement | H23: 90000 | I23: 90 | J23: Proche du centre | K23: Non | L23: Manque d'espace de stockage | N23: Oui , sans condition particulière | O23: Matériel sportif | P23: Non, jamais | R23: 5€ | T23: Prix abordable | V23: Je ne souhaite pas être tenu(e) informé | Z23: J7P5-YA7V | AA23: 05/05/2025 11:25:28 | AC23: 05/05/2025 11:27:28 | AD23: 119.88984 | AE23: FR | AF23: Terminé | AH23: direct | AI23: Smartphone
A24: 23 | B24: Femme | C24: 18-24 ans | D24: Étudiant(e) | F24: Maison | H24: 90340 | I24: 90 | J24: Périphérie | K24: Non | L24: Contraintes budgétaires;Préoccupations environnementales;Réduire l'accumulation d'objets | N24: Oui , sans condition particulière | P24: Non, jamais | Q24: Non, je ne souhaiterai pas payer de cotisation | R24: 10€ | T24: Disponibilité des objets;Prix abordable;Durée de prêt flexible | V24: Je ne souhaite pas être tenu(e) informé | Z24: D429-LRX3 | AA24: 05/05/2025 11:25:55 | AC24: 05/05/2025 11:28:00 | AD24: 124.70232 | AE24: FR | AF24: Terminé | AH24: direct | AI24: Smartphone | AJ24: aa588d67cccf4d2bb8f808dd4fdad167
A25: 24 | B25: Femme | C25: 18-24 ans | D25: Étudiant(e) | F25: Appartement | H25: 9000 | I25: 90 | J25: Proche du centre | K25: Oui | L25: Manque d'espace de stockage;Contraintes budgétaires;Préoccupations environnementales;Réduire l'accumulation d'objets;Éviter les frais d'entretien | N25: Oui , sans condition particulière | O25: Bagagerie | P25: Non, jamais | Q25: Non, je ne souhaiterai pas payer de cotisation | R25: 10€ | T25: Disponibilité des objets | V25: Je ne souhaite pas être tenu(e) informé | Z25: 7ZCD-YGQ2 | AA25: 05/05/2025 11:28:10 | AC25: 05/05/2025 11:31:01 | AD25: 170.867 | AE25: FR | AF25: Terminé | AH25: direct | AI25: Smartphone | AJ25: aa588d67cccf4d2bb8f808dd4fdad167
A26: 25 | B26: Homme | C26: 18-24 ans | D26: Étudiant(e) | F26: Appartement | H26: 90000 | I26: 90 | J26: Proche du centre | K26: Non | L26: Autre : | M26: Essayer des objets sans avoir besoin de les acheter | N26: Non , je souhaite uniquement emprunter | P26: Non, jamais | R26: 5€ | T26: Disponibilité des objets;Facilité de réservation et d'emprunt;Prix abordable;Durée de prêt flexible | V26: Je ne souhaite pas être tenu(e) informé | Z26: DLRB-3JQE | AA26: 05/05/2025 11:33:34 | AC26: 05/05/2025 11:36:17 | AD26: 162.31734 | AE26: FR | AF26: Terminé | AH26: direct | AI26: Smartphone | AJ26: aa588d67cccf4d2bb8f808dd4fdad167
A27: 26 | B27: Femme | C27: 18-24 ans | D27: Étudiant(e) | F27: Maison | H27: 68720 | I27: 68 | J27: Proche du centre | K27: Oui | L27: Manque d'espace de stockage;Préoccupations environnementales;Envie de partager des compétences;Réduire l'accumulation d'objets;Éviter les frais d'entretien | N27: Non , je souhaite uniquement emprunter | P27: Oui, régulièrement | Q27: Non, je ne souhaiterai pas payer de cotisation | R27: 10€ | T27: Prix abordable | V27: Je souhaite être informé(e) des prochaines étapes | W27: KHIDER SATAH | Z27: FR5Y-PZMB | AA27: 05/05/2025 11:37:25 | AC27: 05/05/2025 11:38:36 | AD27: 71.490812 | AE27: FR | AF27: Terminé | AH27: direct | AI27: Smartphone | AJ27: aa588d67cccf4d2bb8f808dd4fdad167
A28: 27 | B28: Femme | C28: 18-24 ans | D28: Étudiant(e) | F28: Maison | H28: 90000 | I28: 90 | J28: Proche du centre | K28: Peut-être | L28: Manque d'espace de stockage;Envie de partager des compétences;Réduire l'accumulation d'objets | N28: Oui , avec certaines conditions | O28: Evènements & fêtes | P28: Non, jamais | Q28: Non, je ne souhaiterai pas payer de cotisation | R28: 10€ | T28: Disponibilité des objets;Facilité de réservation et d'emprunt;Prix abordable;Durée de prêt flexible | V28: Je souhaite être informé(e) des prochaines étapes | W28: Jaber Jana | X28: Jbrjanaa@gmail.com | Y28: 07.83.40.78.17 | Z28: HC6D-8FQH | AA28: 05/05/2025 11:40:57 | AC28: 05/05/2025 11:43:15 | AD28: 138.42663 | AE28: FR | AF28: Terminé | AH28: direct | AI28: Smartphone | AJ28: aa588d67cccf4d2bb8f808dd4fdad167
A29: 28 | B29: Homme | C29: 18-24 ans | D29: Étudiant(e) | F29: Appartement | H29: 25200 | I29: 25 | J29: Proche du centre | K29: Oui | L29: Contraintes budgétaires;Réduire l'accumulation d'objets | N29: Oui , avec certaines conditions | P29: Non, jamais | Q29: Non, je ne souhaiterai pas payer de cotisation | R29: 10€ | T29: Disponibilité des objets;Facilité de réservation et d'emprunt;Prix abordable | V29: Je ne souhaite pas être tenu(e) informé | Z29: 2GDB-7BWV | AA29: 05/05/2025 11:42:28 | AC29: 05/05/2025 11:44:29 | AD29: 121.59131 | AE29: FR | AF29: Terminé | AH29: direct | AI29: Smartphone | AJ29: aa588d67cccf4d2bb8f808dd4fdad167
A30: 29 | B30: Femme | C30: 18-24 ans | D30: Étudiant(e) | F30: Maison | H30: 67230 | I30: 67 | J30: Proche du centre | K30: Non | L30: Contraintes budgétaires;Réduire l'accumulation d'objets | N30: Non , je souhaite uniquement emprunter | P30: Non, jamais | R30: 20 | T30: Disponibilité des objets;Facilité de réservation et d'emprunt;Prix abordable | V30: Je ne souhaite pas être tenu(e) informé | Z30: JHUG-SRHH | AA30: 05/05/2025 11:51:46 | AC30: 05/05/2025 11:54:11 | AD30: 145.02114 | AE30: FR | AF30: Terminé | AH30: direct | AI30: Smartphone | AJ30: aa588d67cccf4d2bb8f808dd4fdad167
A31: 30 | B31: Femme | C31: 18-24 ans | D31: Étudiant(e) | F31: Maison | H31: 25200 | I31: 25 | J31: Centre | K31: Non | L31: Réduire l'accumulation d'objets | N31: Non , je souhaite uniquement emprunter | P31: Non, jamais | R31: 20 | T31: Disponibilité des objets | V31: Je ne souhaite pas être tenu(e) informé | Z31: H2TL-TR2D | AA31: 05/05/2025 11:53:41 | AC31: 05/05/2025 11:55:24 | AD31: 103.16498 | AE31: FR | AF31: Terminé | AH31: direct | AI31: Smartphone | AJ31: aa588d67cccf4d2bb8f808dd4fdad167
A32: 31 | B32: Femme | C32: 18-24 ans | D32: Étudiant(e) | F32: Maison | H32: 70400 | I32: 70 | J32: Proche du centre | K32: Oui | L32: Manque d'espace de stockage;Contraintes budgétaires;Réduire l'accumulation d'objets;Éviter les frais d'entretien | N32: Oui , sans condition particulière | P32: Non, jamais | Q32: Non, je ne souhaiterai pas payer de cotisation | R32: 10€ | T32: Disponibilité des objets;Facilité de réservation et d'emprunt;Prix abordable;Support et explications d'utilisation | V32: Je ne souhaite pas être tenu(e) informé | Z32: 2CSW-KSPA | AA32: 05/05/2025 12:42:25 | AC32: 05/05/2025 12:47:27 | AD32: 301.30643 | AE32: FR | AF32: Terminé | AH32: direct | AI32: Smartphone | AJ32: aa588d67cccf4d2bb8f808dd4fdad167
A33: 32 | B33: Femme | C33: 18-24 ans | D33: Étudiant(e) | F33: Appartement | H33: 25200 | I33: 25 | J33: Proche du centre | K33: Peut-être | L33: Réduire l'accumulation d'objets | N33: Non , je souhaite uniquement emprunter | P33: Oui, occasionnellement | R33: 15€ | T33: Disponibilité des objets;Facilité de réservation et d'emprunt | V33: Je ne souhaite pas être tenu(e) informé | Z33: TVYR-R5WY | AA33: 05/05/2025 13:02:56 | AC33: 05/05/2025 13:05:26 | AD33: 149.74608 | AE33: FR | AF33: Terminé | AH33: direct | AI33: PC | AJ33: aa588d67cccf4d2bb8f808dd4fdad167
A34: 33 | B34: Homme | C34: 18-24 ans | D34: Étudiant(e) | F34: Appartement | H34: 90000 | I34: 90 | J34: Proche du centre | K34: Oui | L34: Contraintes budgétaires | N34: Non , je souhaite uniquement emprunter | P34: Non, jamais | Q34: Non, je ne souhaiterai pas payer de cotisation | R34: 20 | T34: Disponibilité des objets;Facilité de réservation et d'emprunt;Prix abordable;Durée de prêt flexible;Support et explications d'utilisation | V34: Je souhaite être informé(e) des prochaines étapes | W34: LAUGEL Maceo | X34: maceo.laugel@gmail.com | Y34: 06 76 37 19 37 | Z34: KNPF-HXBU | AA34: 05/05/2025 13:22:26 | AC34: 05/05/2025 13:31:13 | AD34: 526.45138 | AE34: FR | AF34: Terminé | AH34: direct | AI34: PC | AJ34: aa588d67cccf4d2bb8f808dd4fdad167
A35: 34 | B35: Femme | C35: 18-24 ans | D35: Étudiant(e) | F35: Maison | H35: 25400 | I35: 25 | J35: Proche du centre | K35: Peut-être | L35: Contraintes budgétaires;Réduire l'accumulation d'objets;Éviter les frais d'entretien | N35: Non , je souhaite uniquement emprunter | P35: Oui, occasionnellement | R35: 10€ | T35: Disponibilité des objets;Facilité de réservation et d'emprunt;Prix abordable | V35: Je ne souhaite pas être tenu(e) informé | Z35: NV9R-FMN2 | AA35: 05/05/2025 16:25:17 | AC35: 05/05/2025 16:27:11 | AD35: 114.06021 | AE35: FR | AF35: Terminé | AH35: direct | AI35: PC | AJ35: aa588d67cccf4d2bb8f808dd4fdad167
A36: 35 | B36: Homme | C36: 18-24 ans | D36: Étudiant(e) | F36: Maison | H36: 25230 | I36: 25 | J36: Zone rurale | K36: Peut-être | L36: Contraintes budgétaires;Réduire l'accumulation d'objets | N36: Oui , avec certaines conditions | O36: Matériel médical | P36: Oui, occasionnellement | Q36: Non, je ne souhaiterai pas payer de cotisation | R36: 10€ | T36: Disponibilité des objets;Facilité de réservation et d'emprunt;Prix abordable;Durée de prêt flexible | V36: Je ne souhaite pas être tenu(e) informé | Z36: YLVD-BDNT | AA36: 06/05/2025 08:20:44 | AC36: 06/05/2025 08:22:53 | AD36: 129.65659 | AE36: FR | AF36: Terminé | AH36: direct | AI36: PC | AJ36: aa588d67cccf4d2bb8f808dd4fdad167
A37: 36 | B37: Homme | C37: 18-24 ans | D37: Étudiant(e) | F37: Maison | H37: 68 | I37: 68 | J37: Centre | K37: Non | L37: Contraintes budgétaires | N37: Non , je souhaite uniquement emprunter | P37: Non, jamais | R37: 5€ | T37: Autre : | V37: Je ne souhaite pas être tenu(e) informé | Z37: K9LW-QQZW | AA37: 06/05/2025 08:22:31 | AC37: 06/05/2025 08:23:43 | AD37: 72.632957 | AE37: FR | AF37: Terminé | AH37: direct | AI37: PC | AJ37: aa588d67cccf4d2bb8f808dd4fdad167
A38: 37 | B38: Femme | C38: 18-24 ans | D38: Étudiant(e) | F38: Appartement | H38: 9000 | I38: 90 | J38: Centre | K38: Non | L38: Éviter les frais d'entretien | N38: Non , je souhaite uniquement emprunter | P38: Non, jamais | R38: Autre : | T38: Prix abordable;Durée de prêt flexible | V38: Je ne souhaite pas être tenu(e) informé | Z38: 2DMX-UNQ8 | AA38: 07/05/2025 14:18:05 | AC38: 07/05/2025 14:21:39 | AD38: 214.03221 | AE38: FR | AF38: Terminé | AH38: direct | AI38: PC | AJ38: aa588d67cccf4d2bb8f808dd4fdad167
A39: 38 | B39: Femme | C39: 18-24 ans | D39: Étudiant(e) | F39: Maison | H39: 25200 | I39: 25 | J39: Proche du centre | K39: Non | L39: Réduire l'accumulation d'objets | N39: Non , je souhaite uniquement emprunter | P39: Non, jamais | R39: 15€ | T39: Prix abordable | V39: Je ne souhaite pas être tenu(e) informé | Z39: WAAY-FHSS | AA39: 07/05/2025 17:27:55 | AC39: 07/05/2025 17:30:41 | AD39: 165.78954 | AE39: FR | AF39: Terminé | AH39: direct | AI39: Smartphone | AJ39: aa588d67cccf4d2bb8f808dd4fdad167
A40: 39 | B40: Femme | C40: 18-24 ans | D40: Étudiant(e) | F40: Maison | H40: 90000 | I40: 90 | J40: Périphérie | K40: Oui | L40: Manque d'espace de stockage | N40: Non , je souhaite uniquement emprunter | P40: Non, jamais | Q40: Non, je ne souhaiterai pas payer de cotisation | R40: 5€ | T40: Durée de prêt flexible | V40: Je ne souhaite pas être tenu(e) informé | Z40: J4UW-VUN3 | AA40: 08/05/2025 14:08:00 | AC40: 08/05/2025 14:13:35 | AD40: 335.01985 | AE40: FR | AF40: Terminé | AH40: direct | AI40: PC | AJ40: aa588d67cccf4d2bb8f808dd4fdad167
...

Sheet Feuil1
A1: Genre | C1: Age | E1: Activité | G1: logement | I1: Code postal | K1: Emplacement du domicile | M1: intérêt pour une BO à Besançon | O1: Motivations | Q1: Partage d'objets
A2: Homme | B2: =COUNTIF(Tableau1[Quels est votre genre ?],Feuil1!A2) -> 25 | C2: 18-24 ans | D2: =COUNTIF(Bibliotheque!C:C,Feuil1!C2) -> 43 | E2: En activité professionnelle | F2: =COUNTIF(Bibliotheque!D:D,Feuil1!E2) -> 43 | G2: Appartement | H2: =COUNTIF(Bibliotheque!F:F,Feuil1!G2) -> 43 | I2: 25 | J2: =COUNTIF(Tableau1[Département],Feuil1!I2) -> 52 | K2: Hyper-centre | L2: =COUNTIF(Bibliotheque!J:J,Feuil1!K2) -> 4 | M2: Oui | N2: =COUNTIF(Tableau1[Une bibliothèque d''objets à Besançon vous intéresserait-elle ?],Feuil1!M2) -> 51 | O2: à reprendre | Q2: Oui , avec certaines conditions | R2: =COUNTIF(Bibliotheque!N:N,Feuil1!Q2) -> 41
A3: Femme | B3: =COUNTIF(Tableau1[Quels est votre genre ?],Feuil1!A3) -> 62 | C3: 25-34 ans | D3: =COUNTIF(Bibliotheque!C:C,Feuil1!C3) -> 12 | E3: Étudiant(e) | F3: =COUNTIF(Bibliotheque!D:D,Feuil1!E3) -> 42 | G3: Maison | H3: =COUNTIF(Bibliotheque!F:F,Feuil1!G3) -> 42 | I3: 90 | J3: =COUNTIF(Tableau1[Département],Feuil1!I3) -> 24 | K3: Centre | L3: =COUNTIF(Bibliotheque!J:J,Feuil1!K3) -> 14 | M3: Non | N3: =COUNTIF(Tableau1[Une bibliothèque d''objets à Besançon vous intéresserait-elle ?],Feuil1!M3) -> 19 | Q3: Non , je souhaite uniquement emprunter | R3: =COUNTIF(Bibliotheque!N:N,Feuil1!Q3) -> 36
A4: Non-binaire | B4: =COUNTIF(Tableau1[Quels est votre genre ?],Feuil1!A4) -> 2 | C4: 35-44 ans | D4: =COUNTIF(Bibliotheque!C:C,Feuil1!C4) -> 22 | E4: Retraité(e) | F4: =COUNTIF(Bibliotheque!D:D,Feuil1!E4) -> 2 | G4: Autre : | H4: =COUNTIF(Bibliotheque!F:F,Feuil1!G4) -> 4 | I4: 68 | J4: =COUNTIF(Tableau1[Département],Feuil1!I4) -> 5 | K4: Proche du centre | L4: =COUNTIF(Bibliotheque!J:J,Feuil1!K4) -> 50 | M4: Peut-être | N4: =COUNTIF(Tableau1[Une bibliothèque d''objets à Besançon vous intéresserait-elle ?],Feuil1!M4) -> 19
C5: 45-54 ans | D5: =COUNTIF(Bibliotheque!C:C,Feuil1!C5) -> 8 | E5: Demandeur / Demandeuse d'emploi | F5: =COUNTIF(Bibliotheque!D:D,Feuil1!E5) -> 1 | I5: 67 | J5: =COUNTIF(Tableau1[Département],Feuil1!I5) -> 1 | K5: Périphérie | L5: =COUNTIF(Bibliotheque!J:J,Feuil1!K5) -> 8
C6: 55-64 ans | D6: =COUNTIF(Bibliotheque!C:C,Feuil1!C6) -> 3 | K6: Zone rurale | L6: =COUNTIF(Bibliotheque!J:J,Feuil1!K6) -> 13
C7: 65 ans et plus | D7: =COUNTIF(Bibliotheque!C:C,Feuil1!C7) -> 1

Sheet Contacts
A1: E-mail :
A3: aubertin.thibault@gmail.com
A4: molheratcaroline@yahoo.fr
A5: Alice.humbert1@orange.fr
A6: charmoilledesiree@yahoo.fr
A7: chazalannececile@gmail.com
A8: aurelie.thiebaud@yahoo.fr
A9: cecile.vouillot@gmail.com
A10: xavier.brand@free.fr
A11: piou25@laposte.net
A12: vincent25@zaclys.net
A13: mariannegeslin@yahoo.com
... A38: chrisburet@lilo.org
